Workbook
Name asdf: '10 - Mi'!$A$1:$D$64
Name asdf: '15 - Mo'!$A$1:$D$66
Name fdsa: '11 - Do'!$A$1:$D$64
Name fdsa: '9 - Di'!$A$1:$D$64
Name Montag: 'WAP - KVK'!#REF!
Name Montag: 'WAP - Wo 1'!#REF!
Name Montag: 'WAP - Wo 2'!#REF!
Name Montag: 'WAP - Wo 3'!#REF!
Name Of: #REF!
Name Rapporte: #REF!
Name Rapporte: #REF!
Name Räumlichkeiten: #REF!
Name Räumlichkeiten: #REF!
Name Startdatum: 'WAP - KVK'!$L$1
Name Startdatum: 'WAP - Wo 1'!$K$1
Name Startdatum: 'WAP - Wo 2'!$L$1
Name Startdatum: 'WAP - Wo 3'!$M$1
Name Startdatum: [1]VORLAGE!$K$4
Name Status: #REF!
Name Status: #REF!
Name Tätigkeiten: #REF!
Name Tätigkeiten: #REF!
Name Verantwortung: #REF!
Name Verantwortung: #REF!

Sheet Einstellungen
B2: Allgemeine Einstellungen
B4: Allgemein
B5: Name Kp | C5: Ter Div Stabskp 3
B6: Start Dienstleistung | C6: 46286
B9: Zeiten
B10: Tagwache | C10: 0545
B11: Morgenessen | C11: 0600-0700
B12: Mittagessen | C12: 1200-1300
B13: Abendessen | C13: 1800-1900
B14: AV Morgen | C14: 0715
B15: HV gross | C15: 1845
B16: HV klein | C16: 1945
B17: HV Urlaub | C17: 1800
B18: ABV | C18: 2230
B19: PD/ID | C19: 2130-2230
B22: Wochenstarts
B23: Woche | C23: Datum | D23: Nr
B24: WKW0 | C24: 46286 | D24: 0
B25: WKW1 | C25: 46293 | D25: 7
B26: WKW2 | C26: 46300 | D26: 14
B27: WKW3 | C27: 46307 | D27: 21
B31: Personell
B33: Kp Kdt: | D33: Höheres Kader | G33: Tagesof | J33: Wachtof | M33: Wachtof WoE | P33: Tel KP Stabskp | R33: Tel LVZ/MCC
B34: Hptm Isler, Rolf | D34: Hptm Isler | G34: Datum | H34: Wer | J34: Woche | K34: Wer | M34: Woche | N34: Wer | P34: (noch nicht bekannt) | R34: (noch nicht bekannt)
D35: Oblt Sieber | G35: 46286 | H35: Oblt Sieber | J35: WKW0 | K35: Lt Christophe Lopez-Polo | M35: WKW0 | N35: Lt Lopez-Polo
B36: Kp Kdt Stv: | D36: Oblt Coduri | G36: 46287 | H36: Lt Gemeinder | J36: WKW1 | K36: Lt Christophe Lopez-Polo | M36: WKW1 | N36: Lt Omura | P36: Tel Tagesof | R36: Tel Wacht Of
B37: Oblt Sieber, Dario | D37: Lt Gemeinder | G37: 46288 | H37: Lt Köchli | J37: WKW2 | K37: Lt Christophe Lopez-Polo | M37: WKW2 | N37: Lt Lehner | P37: (noch nicht bekannt) | R37: (noch nicht bekannt)
D38: Lt Koç | G38: 46289 | H38: Lt Lehner | J38: WKW3 | K38: Lt Christophe Lopez-Polo | M38: WKW3 | N38: -
B39: Zugliste | D39: Lt Christophe Lopez-Polo | G39: 46290 | H39: Lt Christophe Lopez-Polo
B40: Kdo Zug | D40: Lt Omura | G40: 46291 | H40: Lt Lopez-Polo
B41: Log Zug | D41: Lt Lehner | G41: 46292 | H41: Lt Lopez-Polo
B42: Stabsz Bat | D42: Lt Köchli | G42: 46293 | H42: Oblt Sieber
B43: Stabsz Gs Vb | D43: Adj Uof Heusser | G43: 46294 | H43: Lt Gemeinder
B44: Syst Z | D44: Fur Cattaneo | G44: 46295 | H44: Lt Köchli
D45: (noch nicht bekannt) | G45: 46296 | H45: Lt Lehner
B46: Bat Kdt | G46: 46297 | H46: Lt Christophe Lopez-Polo
B47: Maj i Gst Ciarulli, Giovanni | G47: 46298 | H47: Lt Omura
G48: 46299 | H48: Lt Omura
G49: 46300 | H49: Oblt Sieber
G50: 46301 | H50: Lt Gemeinder
...

Sheet WAP - KVK
B1: Wochenarbeitsplan KVK | M1: =_xlfn.CONCAT(TEXT(Einstellungen!$C$6,"DD.MM.YYYY")," bis ",TEXT(Einstellungen!$C$6+6,"DD.MM.YYYY")) -> 21.09.2026 bis 27.09.2026
BJ4: Einheit / unità: Ter Div Stabskp 3
B5: Zeit | C5: Montag / Lunedì | K5: Dienstag / Martedì | S5: Mittwoch / Mercoledì | AA5: Donnerstag / Giovedì | AI5: Freitag / Venerdì | AQ5: Samstag / Samedi | AY5: Sonntag / Domenica | BG5: Zeit | BH5: Bemerkungen / Observations
B6: heure | C6: =Einstellungen!$C$6 -> 46286 | K6: =C6+1 -> 46287 | S6: =K6+1 -> 46288 | AA6: =S6+1 -> 46289 | AI6: =AA6+1 -> 46290 | AQ6: =AI6+1 -> 46291 | AY6: =AQ6+1 -> 46292 | BG6: heure
C7: Kdo | D7: Log | E7: Stabsz Bat | F7: Wach Det | G7: Of | H7: Uof | I7: Rap | J7: Beso | K7: Kdo | L7: Log | M7: Stabsz Bat | N7: Wach Det | O7: Of | P7: Uof | Q7: Rap | R7: Beso | S7: Kdo | T7: Log | U7: Stabsz Bat | V7: Wach Det | W7: Of | X7: Uof | Y7: Rap | Z7: Beso | AA7: Kdo | AB7: Log | AC7: Stabsz Bat | AD7: Wach Det | AE7: Of | AF7: Uof | AG7: Rap | AH7: Beso | AI7: Kdo | AJ7: Log | AK7: Stabsz Bat | AL7: Wach Det | AM7: Of | AN7: Uof | AO7: Rap | AP7: Beso | AQ7: Kp | AW7: Rap | AX7: Beso | AY7: Kp | BE7: Rap | BF7: Beso | BI7: Stand: | BJ7: =TODAY() -> 46267
B9: 0500 | BG9: 0500 | BI9: Rapporte:
BI10: BR: Bataillonsrapport;
BI11: KR: Kompanierapport
BI12: DR: Dienstrapport
B13: 0600 | BG13: 0600 | BI13: AR: Ausbildungsrapport
BI16: Telefonnummern
B17: 0700 | BG17: 0700 | BI17: =_xlfn.CONCAT("KP: ",Einstellungen!$P$34) -> KP: (noch nicht bekannt)
BI18: =_xlfn.CONCAT("LVZ/MCC: ",Einstellungen!$R$34) -> LVZ/MCC: (noch nicht bekannt)
BI19: =_xlfn.CONCAT("Tagesof: ",Einstellungen!$P$37) -> Tagesof: (noch nicht bekannt)
BI20: =_xlfn.CONCAT("Wachtof: ",Einstellungen!$R$37) -> Wachtof: (noch nicht bekannt)
B21: 0800 | BG21: 0800
BI23: Wochenziele
BI24: - Erfolgreiche Durchführung des zentralen KVK - Kader sind vorbereitet für den ADF - Ausbildungen und Vb Trainings sind geplant
B25: 0900 | BG25: 0900
B29: 1000 | BG29: 1000
B33: 1100 | BG33: 1100
B37: 1200 | BG37: 1200
B41: 1300 | BG41: 1300
B45: 1400 | BG45: 1400
B49: 1500 | BG49: 1500
B53: 1600 | BG53: 1600
B57: 1700 | BG57: 1700
B61: 1800 | BG61: 1800
B65: 1900 | BG65: 1900
B69: 2000 | BG69: 2000
BI70: Ter Div Stabskp 3
BI72: #VALUE!
B73: 2100 | BG73: 2100
B77: 2200 | BG77: 2200
BI80: Hptm Rolf Isler Kdt
B81: 2300 | BG81: 2300
C116: Montag / lundi | K116: Dienstag / Mardi | S116: Mittwoch / Mercredi | AA116: Donnerstag / Jeudi | AI116: Freitag / Vendredi | AQ116: Samstag / Samedi | AY116: Samstag / Samedi
C117: =Einstellungen!$C$6 -> 46286 | K117: =C117+1 -> 46287 | S117: =K117+1 -> 46288 | AA117: =S117+1 -> 46289 | AI117: =AA117+1 -> 46290 | AQ117: =AI117+1 -> 46291 | AY117: =AQ117+1 -> 46292
B118: Termine / Info | C118: 10 | D118: Synchro LVZ mit Zfhr Stabsz Bat, Bat KP (S1) | K118: 20 | L118: Erkundung Spl CHUR (S2, UL ADF 2026) | S118: 30 | T118: LVZ zG Bat Stab einsatzbereit (Stabsz Bat) | AA118: 40 | AB118: Fsg Kp Apotheke, MZR CHUR (Az)
C119: 11 | D119: AR 1 für KU Mi & Do, Bat KP (Kdt Stv) | K119: 21 | L119: Start Betrieb Bat Kanzlei (Stabsz Bat) | S119: 31 | T119: AR 2 für KU (GS), gem Bf | AA119: 41 | AB119: Ausb FU Planer Uem Stao Wahl (S6)
...

Sheet WAP - Wo 1
B1: Wochenarbeitsplan Woche 1 | N1: =_xlfn.CONCAT(TEXT(Einstellungen!$C$6+7,"DD.MM.YYYY")," bis ",TEXT(Einstellungen!$C$6+13,"DD.MM.YYYY")) -> 28.09.2026 bis 04.10.2026
BC4: Einheit / unità: Ter Div Stabskp 3
B5: Zeit | C5: Montag / Lunedì | J5: Dienstag / Martedì | Q5: Mittwoch / Mercoledì | X5: Donnerstag / Giovedì | AE5: Freitag / Venerdì | AL5: Samstag / Samedi | AS5: Sonntag / Domenica | AZ5: Zeit | BA5: Bemerkungen / Observations
B6: heure | C6: ='WAP - KVK'!$AY$6+1 -> 46293 | J6: =C6+1 -> 46294 | Q6: =J6+1 -> 46295 | X6: =Q6+1 -> 46296 | AE6: =X6+1 -> 46297 | AL6: =AE6+1 -> 46298 | AS6: =AL6+1 -> 46299 | AZ6: heure
C7: CAPO DUE | D7: Shuttle Rivera | E7: Shuttle & Tirage Chur | F7: Rest Trp | H7: Rap | I7: Beso | J7: Kdo Z | K7: Log & VT | L7: Stabsz Bat | M7: Stabsz Gs Vb | N7: Syst Z | O7: Rap | P7: Beso | Q7: Kdo Z | R7: Log & VT | S7: Stabsz Bat | T7: Stabsz Gs Vb | U7: Syst Z | V7: Rap | W7: Beso | X7: Kdo Z | Y7: Log & VT | Z7: Stabsz Bat | AA7: Stabsz Gs Vb | AB7: Syst Z | AC7: Rap | AD7: Beso | AE7: Kdo Z | AF7: Log & VT | AG7: Stabsz Bat | AH7: Stabsz Gs Vb | AI7: Syst Z | AJ7: Rap | AK7: Beso | AL7: Kp | AQ7: Rap | AR7: Beso | AS7: Kp | AX7: Rap | AY7: Beso | BB7: Stand: | BC7: =TODAY() -> 46267
B9: 0500 | AZ9: 0500 | BB9: Rapporte:
BB10: BR: Bataillonsrapport;
BB11: KR: Kompanierapport
BB12: DR: Dienstrapport
B13: 0600 | AZ13: 0600 | BB13: AR: Ausbildungsrapport
BB16: Telefonnummern
B17: 0700 | AZ17: 0700 | BB17: =_xlfn.CONCAT("KP: ",Einstellungen!$P$34) -> KP: (noch nicht bekannt)
BB18: =_xlfn.CONCAT("LVZ/MCC: ",Einstellungen!$R$34) -> LVZ/MCC: (noch nicht bekannt)
BB19: =_xlfn.CONCAT("Tagesof: ",Einstellungen!$P$37) -> Tagesof: (noch nicht bekannt)
BB20: =_xlfn.CONCAT("Wachtof: ",Einstellungen!$R$37) -> Wachtof: (noch nicht bekannt)
B21: 0800 | AZ21: 0800
B25: 0900 | AZ25: 0900
B29: 1000 | AZ29: 1000
B33: 1100 | AZ33: 1100
B37: 1200 | AZ37: 1200
B41: 1300 | AZ41: 1300
B45: 1400 | AZ45: 1400
B49: 1500 | AZ49: 1500
B53: 1600 | AZ53: 1600
B57: 1700 | AZ57: 1700
B61: 1800 | AZ61: 1800
B65: 1900 | AZ65: 1900
B69: 2000 | AZ69: 2000
BB70: Ter Div Stabskp 3
BB72: #VALUE!
B73: 2100 | AZ73: 2100
B77: 2200 | AZ77: 2200
BB80: Hptm Rolf Isler Kdt
B81: 2300 | AZ81: 2300
C116: Montag / lundi | J116: Dienstag / Mardi | Q116: Mittwoch / Mercredi | X116: Donnerstag / Jeudi | AE116: Freitag / Vendredi | AL116: Samstag / Samedi | AS116: Samstag / Samedi
C117: ='WAP - KVK'!$AY$6+1 -> 46293 | J117: =C117+1 -> 46294 | Q117: =J117+1 -> 46295 | X117: =Q117+1 -> 46296 | AE117: =X117+1 -> 46297 | AL117: =AE117+1 -> 46298 | AS117: =AL117+1 -> 46299
B118: Termine / Info | C118: 10 | J118: 20 | K118: BBZ MCC an LVZ Bat | X118: 40 | Y118: TBZ inkl WachtD Stufe 4 HQ BRIGELS
C119: 11 | J119: 21 | K119: Slot RA-Stelle für AWB-Karten
J120: 22
B126: Tagesof | C126: =VLOOKUP(C117,Einstellungen!$G$34:$H$60,2,FALSE) -> Oblt Sieber | J126: =VLOOKUP(J117,Einstellungen!$G$34:$H$60,2,FALSE) -> Lt Gemeinder | Q126: =VLOOKUP(Q117,Einstellungen!$G$34:$H$60,2,FALSE) -> Lt Köchli | X126: =VLOOKUP(X117,Einstellungen!$G$34:$H$60,2,FALSE) -> Lt Lehner | AE126: =VLOOKUP(AE117,Einstellungen!$G$34:$H$60,2,FALSE) -> Lt Christophe Lopez-Polo | AL126: =VLOOKUP(AL117,Einstellungen!$G$34:$H$60,2,FALSE) -> Lt Omura | AS126: =VLOOKUP(AS117,Einstellungen!$G$34:$H$60,2,FALSE) -> Lt Omura

Sheet WAP - Wo 2
B1: Wochenarbeitsplan Woche 2 | L1: =_xlfn.CONCAT(TEXT(Einstellungen!$C$6+14,"DD.MM.YYYY")," bis ",TEXT(Einstellungen!$C$6+20,"DD.MM.YYYY")) -> 05.10.2026 bis 11.10.2026
BC4: Einheit / unità: Ter Div Stabskp 3
B5: Zeit | C5: Montag / Lunedì | J5: Dienstag / Martedì | Q5: Mittwoch / Mercoledì | X5: Donnerstag / Giovedì | AE5: Freitag / Venerdì | AL5: Samstag / Samedi | AS5: Sonntag / Domenica | AZ5: Zeit | BA5: Bemerkungen / Observations
B6: heure | C6: ='WAP - Wo 1'!$AS$6+1 -> 46300 | J6: =C6+1 -> 46301 | Q6: =J6+1 -> 46302 | X6: =Q6+1 -> 46303 | AE6: =X6+1 -> 46304 | AL6: =AE6+1 -> 46305 | AS6: =AL6+1 -> 46306 | AZ6: heure
C7: Kdo Z | D7: Log & VT | E7: Stabsz Bat | F7: Stabsz Gs Vb | G7: Syst Z | H7: Rap | I7: Beso | J7: Kdo Z | K7: Log & VT | L7: Stabsz Bat | M7: Stabsz Gs Vb | N7: Syst Z | O7: Rap | P7: Beso | Q7: Kdo Z | R7: Log & VT | S7: Stabsz Bat | T7: Stabsz Gs Vb | U7: Syst Z | V7: Rap | W7: Beso | X7: Kdo Z | Y7: Log & VT | Z7: Stabsz Bat | AA7: Stabsz Gs Vb | AB7: Syst Z | AC7: Rap | AD7: Beso | AE7: Kdo Z | AF7: Log & VT | AG7: Stabsz Bat | AH7: Stabsz Gs Vb | AI7: Syst Z | AJ7: Rap | AK7: Beso | AL7: Kp | AQ7: Rap | AR7: Beso | AS7: Kp | AX7: Rap | AY7: Beso | BB7: Stand: | BC7: =TODAY() -> 46267
B9: 0500 | AZ9: 0500 | BB9: Rapporte:
BB10: BR: Bataillonsrapport;
BB11: KR: Kompanierapport
BB12: DR: Dienstrapport
B13: 0600 | AZ13: 0600 | BB13: AR: Ausbildungsrapport
BB16: Telefonnummern
B17: 0700 | AZ17: 0700 | BB17: =_xlfn.CONCAT("KP: ",Einstellungen!$P$34) -> KP: (noch nicht bekannt)
BB18: =_xlfn.CONCAT("LVZ/MCC: ",Einstellungen!$R$34) -> LVZ/MCC: (noch nicht bekannt)
BB19: =_xlfn.CONCAT("Tagesof: ",Einstellungen!$P$37) -> Tagesof: (noch nicht bekannt)
BB20: =_xlfn.CONCAT("Wachtof: ",Einstellungen!$R$37) -> Wachtof: (noch nicht bekannt)
B21: 0800 | AZ21: 0800
B25: 0900 | AZ25: 0900
B29: 1000 | AZ29: 1000
B33: 1100 | AZ33: 1100
B37: 1200 | AZ37: 1200
B41: 1300 | AZ41: 1300
B45: 1400 | AZ45: 1400
B49: 1500 | AZ49: 1500
B53: 1600 | AZ53: 1600
B57: 1700 | AZ57: 1700
B61: 1800 | AZ61: 1800
B65: 1900 | AZ65: 1900
B69: 2000 | AZ69: 2000
BB70: Ter Div Stabskp 3
BB72: #VALUE!
B73: 2100 | AZ73: 2100
B77: 2200 | AZ77: 2200
BB80: Hptm Rolf Isler Kdt
B81: 2300 | AZ81: 2300
C116: Montag / Lunedì | J116: Dienstag / Martedì | Q116: Mittwoch / Mercoledì | X116: Donnerstag / Giovedì | AE116: Freitag / Venerdì | AL116: Samstag / Samedi | AS116: Sonntag / Domenica
C117: ='WAP - Wo 1'!$AS$6+1 -> 46300 | J117: =C117+1 -> 46301 | Q117: =J117+1 -> 46302 | X117: =Q117+1 -> 46303 | AE117: =X117+1 -> 46304 | AL117: =AE117+1 -> 46305 | AS117: =AL117+1 -> 46306
B118: Termine / Info | C118: 10 | D118: Zwischenrevision (Four/Qm) | AE118: 50 | AF118: Meldung erfolgte Kü Insp an Qm
B126: Tagesof | C126: =VLOOKUP(C117,Einstellungen!$G$34:$H$60,2,FALSE) -> Oblt Sieber | J126: =VLOOKUP(J117,Einstellungen!$G$34:$H$60,2,FALSE) -> Lt Gemeinder | Q126: =VLOOKUP(Q117,Einstellungen!$G$34:$H$60,2,FALSE) -> Lt Köchli | X126: =VLOOKUP(X117,Einstellungen!$G$34:$H$60,2,FALSE) -> Lt Lehner | AE126: =VLOOKUP(AE117,Einstellungen!$G$34:$H$60,2,FALSE) -> Lt Christophe Lopez-Polo | AL126: =VLOOKUP(AL117,Einstellungen!$G$34:$H$60,2,FALSE) -> Lt Lehner | AS126: =VLOOKUP(AS117,Einstellungen!$G$34:$H$60,2,FALSE) -> Lt Lehner

Sheet WAP - Wo 3
B1: Wochenarbeitsplan Woche 3 | M1: =_xlfn.CONCAT(TEXT(Einstellungen!$C$6+21,"DD.MM.YYYY")," bis ",TEXT(Einstellungen!$C$6+27,"DD.MM.YYYY")) -> 12.10.2026 bis 18.10.2026
BC4: Einheit / unità: Ter Div Stabskp 3
B5: Zeit | C5: Montag / Lunedì | J5: Dienstag / Martedì | Q5: Mittwoch / Mercoledì | X5: Donnerstag / Giovedì | AE5: Freitag / Venerdì | AL5: Samstag / Samedi | AS5: Sonntag / Domenica | AZ5: Zeit | BA5: Bemerkungen / Observations
B6: heure | C6: ='WAP - Wo 2'!$AS$6+1 -> 46307 | J6: =C6+1 -> 46308 | Q6: =J6+1 -> 46309 | X6: =Q6+1 -> 46310 | AE6: =X6+1 -> 46311 | AL6: =AE6+1 -> 46312 | AS6: =AL6+1 -> 46313 | AZ6: heure
C7: Kdo Z | D7: Log & VT | E7: Stabsz Bat | F7: Stabsz Gs Vb | G7: Syst Z | H7: Rap | I7: Beso | J7: Kdo Z | K7: Log & VT | L7: Stabsz Bat | M7: Stabsz Gs Vb | N7: Syst Z | O7: Rap | P7: Beso | Q7: Kdo Z | R7: Log & VT | S7: Stabsz Bat | T7: Stabsz Gs Vb | U7: Syst Z | V7: Rap | W7: Beso | X7: Kdo Z | Y7: Log & VT | Z7: Stabsz Bat | AA7: Stabsz Gs Vb | AB7: Syst Z | AC7: Rap | AD7: Beso | AE7: Kdo Z | AF7: Log & VT | AG7: Stabsz Bat | AH7: Stabsz Gs Vb | AI7: Syst Z | AJ7: Rap | AK7: Beso | AL7: Kp | AQ7: Rap | AR7: Beso | AS7: Kp | AX7: Rap | AY7: Beso | BB7: Stand: | BC7: =TODAY() -> 46267
B9: 0500 | AZ9: 0500 | BB9: Rapporte:
BB10: BR: Bataillonsrapport;
BB11: KR: Kompanierapport
BB12: DR: Dienstrapport
B13: 0600 | AZ13: 0600 | BB13: AR: Ausbildungsrapport
BB16: Telefonnummern
B17: 0700 | AZ17: 0700 | BB17: =_xlfn.CONCAT("KP: ",Einstellungen!$P$34) -> KP: (noch nicht bekannt)
BB18: =_xlfn.CONCAT("LVZ/MCC: ",Einstellungen!$R$34) -> LVZ/MCC: (noch nicht bekannt)
BB19: =_xlfn.CONCAT("Tagesof: ",Einstellungen!$P$37) -> Tagesof: (noch nicht bekannt)
BB20: =_xlfn.CONCAT("Wachtof: ",Einstellungen!$R$37) -> Wachtof: (noch nicht bekannt)
B21: 0800 | AZ21: 0800
B25: 0900 | AZ25: 0900
B29: 1000 | AZ29: 1000
B33: 1100 | AZ33: 1100
B37: 1200 | AZ37: 1200
B41: 1300 | AZ41: 1300
B45: 1400 | AZ45: 1400
B49: 1500 | AZ49: 1500
B53: 1600 | AZ53: 1600
B57: 1700 | AZ57: 1700
B61: 1800 | AZ61: 1800
B65: 1900 | AZ65: 1900
B69: 2000 | AZ69: 2000
BB70: Ter Div Stabskp 3
BB72: #VALUE!
B73: 2100 | AZ73: 2100
B77: 2200 | AZ77: 2200
BB80: Hptm Rolf Isler Kdt
B81: 2300 | AZ81: 2300
C116: Montag / lundi | J116: Dienstag / Mardi | Q116: Mittwoch / Mercredi | X116: Donnerstag / Jeudi | AE116: Freitag / Vendredi | AL116: Samstag / Samedi | AS116: Samstag / Samedi
C117: ='WAP - Wo 2'!$AS$6+1 -> 46307 | J117: =C117+1 -> 46308 | Q117: =J117+1 -> 46309 | X117: =Q117+1 -> 46310 | AE117: =X117+1 -> 46311 | AL117: =AE117+1 -> 46312 | AS117: =AL117+1 -> 46313
B118: Termine / Info | C118: 10 | Q118: 30 | R118: Stabsbat Challenge
C119: 11 | Q119: 31 | R119: Schlussrevision (Four/Qm)
Q120: 32 | R120: Abbau Zaunelemente
Q121: 33 | R121: Abgabe Zaunelemente, VOL Chur
...

Sheet 1 - Mo
F1: Status: | G1: Bereit für Kdt | N1: Index
A2: Ter Div Stabsbat 3 - zentraler KVK | D2: =IF(EXACT($G$1,"Genehmigt durch Kdt"),"","PROVISORISCH") -> PROVISORISCH | N2: 1
A3: Tagesbefehl / Ordine del giorno
A6: ="Tagesbefehl Nr " & $N$2 & " für " & UPPER(TEXT($N$2+1,"[$-407]dddd")) & ", " & TEXT(Einstellungen!C6+$N$2-1,"DD.MM.YYYY") -> Tagesbefehl Nr 1 für MONTAG, 21.09.2026 | C6: =CONCATENATE("Gültig ab:") -> Gültig ab: | D6: =TODAY() -> 46267
C7: Revision: | D7: -
C8: Ersetzt version: | D8: -
A10: Zeit | B10: Aktivität | C10: Verantwortung | D10: Standort
A11: 1 Dienstbetrieb / Ausbildung - Operazioni di servizio / formazione
A13: Alle
A14: 1200-1300 | B14: Mittagessen / pranzo (SESO) | C14: Einh Fur Stabskp | D14: Esssaal / refettorio
A15: 1800-1845 | B15: Nachtessen / cena | C15: Einh Fur Stabskp | D15: Esssaal / refettorio
A16: 1900-2000 | B16: Regieanweisungen KVK | C16: Einh Kdt Stabskp | D16: ThS Bonaduz
A17: 2200-2300 | B17: PD/ID | C17: Zfhr / caposez | D17: Ukft / acc
A18: 2300 | B18: ABV / APS | C18: Einh Fw / sgtm U | D18: Ukft / acc
A20: Stab
A21: 0930-1030 | B21: Einrücken | C21: Bat Kdt Stv / SC | D21: MZG Bonaduz
A22: 1030-1200 | B22: Eintrittstheorie Kdt | C22: Bat Kdt | D22: ThS Bonaduz
A23: 1300-1615 | B23: Erstellen Fhr Fähigkeit | C23: Bat Kdt Stv / SC | D23: Bat KP
A24: 1630-1800 | B24: Ausb DPSA | C24: Extern | D24: MZG Bonaduz
A25: 2000-2200 | B25: Stabsarbeit | C25: Bat Kdt Stv / SC | D25: Bat KP
A27: Einh Kdt
A28: 0930-1030 | B28: Einrücken | C28: Kp Kdt / cdt cp | D28: MZG Bonaduz
A29: 1030-1200 | B29: Erstellen Fhr Fähigkeit | C29: Kp Kdt / cdt cp | D29: MZG Bonaduz
A30: 1300-1400 | B30: Eintrittstheorie Kdt | C30: Bat Kdt | D30: Rapportraum
A31: 1400-1630 | B31: AVOR | C31: Kp Kdt / cdt cp | D31: MZG Bonaduz
A32: 1630-1800 | B32: Ausb DPSA | C32: Extern | D32: MZG Bonaduz
A33: 2000-2200 | B33: AVOR | C33: Kp Kdt / cdt cp | D33: MZG Bonaduz
A35: Zfhr
A36: 1300-1400 | B36: Einrücken | C36: Kp Kdt / cdt cp | D36: MZG Bonaduz
A37: 1400-1800 | B37: AVOR | C37: Kp Kdt / cdt cp | D37: MZG Bonaduz
A38: 2000-2200 | B38: AVOR | C38: Kp Kdt / cdt cp | D38: MZG Bonaduz
A40: Truppe Stabskp
A41: gem MBK | B41: Einrücken Det-weise | C41: Det C | D41: gem Befehl
A42: gz Tag | B42: gem Bf Det C | C42: Det C | D42: gem Befehl
A43: 1500-1600 | B43: Regierungserklärung (alle höh Kader) | C43: Kp Kdt / cdt cp | D43: Rapportraum
A44: 1600-1700 | B44: AR 0 (alle höh Kader) | C44: Kp Kdt / cdt cp | D44: Rapportraum
A46: 2 Besonderes - Caratteristiche speciali
A48: ab 0930 | B48: WAT Stufe 2 | C48: Wacht Of | D48: MZG Bonaduz & Bat KP
A49: 1030 | B49: Abfahrt Bus Rivera - ALC-M | C49: Det C | D49: Bhf Rivera
A50: 1200 | B50: Fassung Lunch Vpf Zen MCE | C50: Det C | D50: MCE
...

Sheet 2 - Di
F1: Status: | G1: Bereit für Kdt | N1: Index
A2: Ter Div Stabsbat 3 - zentraler KVK | D2: =IF(EXACT($G$1,"Genehmigt durch Kdt"),"","PROVISORISCH") -> PROVISORISCH | N2: 2
A3: Tagesbefehl / Ordine del giorno
A6: ="Tagesbefehl Nr " & $N$2 & " für " & UPPER(TEXT($N$2+1,"[$-407]dddd")) & ", " & TEXT(Einstellungen!C6+$N$2-1,"DD.MM.YYYY") -> Tagesbefehl Nr 2 für DIENSTAG, 22.09.2026 | C6: =CONCATENATE("Gültig ab:") -> Gültig ab: | D6: =TODAY() -> 46267
C7: Revision: | D7: -
C8: Ersetzt version: | D8: -
A10: Zeit | B10: Aktivität | C10: Verantwortung | D10: Standort
A11: 1 Dienstbetrieb / Ausbildung - Operazioni di servizio / formazione
A13: Alle
A14: 0545 | B14: Tagwache / diane | C14: Kp Kdt / cdt cp | D14: Ukft / acc
A15: 0600-0645 | B15: Morgenessen / colazione | C15: Einh Fur Stabskp | D15: Esssaal / refettorio
A16: 0645 | B16: AV / APE | C16: Einh Kdt Stabskp | D16: AV-Platz / piazza d'appello
A17: 1200-1300 | B17: Mittagessen / pranzo | C17: Einh Fur Stabskp | D17: Esssaal / refettorio
A18: 1300-1415 | B18: Korpsvisite, Kdt TD3. Tn: Of + höh Uof | C18: Extern | D18: ThS Bonaduz
A19: 1530-1630 | B19: KU Cyber | C19: S2 | D19: ThS Bonaduz
A20: 1630-1800 | B20: Ausb MND | C20: Extern | D20: MZG Bonaduz
A21: 1800-2000 | B21: Nachtessen / cena | C21: Einh Fur Stabskp | D21: Esssaal / refettorio
A22: 2200-2300 | B22: PD/ID | C22: Kp Kdt / cdt cp | D22: Ukft / acc
A23: 2300 | B23: ABV / APS | C23: Kp Kdt / cdt cp | D23: Ukft / acc
A25: Stab
A26: 0900-1200 | B26: Stabsarbeit | C26: Bat Kdt Stv / SC | D26: Bat KP
A27: 1430-1515 | B27: Sync Rap KVK | C27: Bat Kdt Stv / SC | D27: ThS Bonaduz
A29: Einh Kdt
A30: 0700-1200 | B30: AVOR | C30: Kp Kdt / cdt cp | D30: MZG Bonaduz
A31: 1430-1515 | B31: Sync Rap KVK | C31: Bat Kdt Stv / SC | D31: ThS Bonaduz
A33: Zfhr
A34: 0700-1200 | B34: AVOR | C34: Kp Kdt / cdt cp | D34: MZG Bonaduz
A35: 1430-1515 | B35: Eintrittstheorie Kdt | C35: Bat Kdt | D35: ThS Bonaduz
A37: höh Uof
A38: 0930-1030 | B38: Einrücken | C38: Kp Kdt / cdt cp | D38: MZG Bonaduz
A39: 1030-1200 | B39: z Vf Kp Kdt | C39: Kp Kdt / cdt cp | D39: MZG Bonaduz
A40: 1430-1515 | B40: Eintrittstheorie Kdt | C40: Bat Kdt | D40: ThS Bonaduz
A42: Grfhr
A43: 1700-1800 | B43: Einrücken | C43: Kp Kdt / cdt cp | D43: MZG Bonaduz
A44: 1900-2000 | B44: Eintrittstheorie Kdt | C44: Bat Kdt | D44: ThS Bonaduz
A46: Truppe Stabskp
